<?xml version="1.0" ?>
<!-- =================================================================================== -->
<!-- |    This document was autogenerated by xacro from kuka_lwr_arm.urdf.xacro        | -->
<!-- |    EDITING THIS FILE BY HAND IS NOT RECOMMENDED                                 | -->
<!-- =================================================================================== -->

<robot name="Left_Arm_Robot">

 <link name="Link02">
  <inertial>
   <mass value="0">
   <origin rpy="1.5707963267948966 0 1.5707963267948966"xyz="0 0 400"/>
   <inertia ixx="0.00381666666667" ixy="0" ixz="0" iyy="0.0036" iyz="0" izz="0.00381666666667"/>
  </inertial>
  <visual>
   <origin rpy="1.5707963267948966 0 1.5707963267948966"xyz="0 0 400"/>
   <geometry>
    <mesh filename="Link02.stl">
   </geometry>
  </visual>
  <collision>
   <origin rpy="1.5707963267948966 0 1.5707963267948966" xyz="180 0 -24"/>
   <geometry>
    <mesh filename="Link02_CH.stl"
   </geometry>
  </collision>
 </link>
   
 <joint name="joint2" type="revolute">
  <origin rpy="1.5707963267948966 0 1.5707963267948966" xyz="0 0 0.11"/>
  <axis xyz="0 0 1"/>
  <limit effort="204" lower="-2.96705972839" upper="2.96705972839" velocity="1.91986217719"/>
  <dynamics damping="0.1"/>
  <parent link="Link02"/>
  <child link="Link03"/>
 </joint>

 <transmission name="Link2_3_trans" type="pr2_mechanism_model/SimpleTransmission">
  <actuator name="Link2_3_motor"/>
  <joint name="joint2"/>
  <mechanicalReduction>1.0</mechanicalReduction>
 </transmission>

 <link name="Link03">
  <inertial>
   <mass value="0">
   <origin rpy="0 0 0.23265238929084414"xyz="155 35.73668544 116"/>
   <inertia ixx="0.00381666666667" ixy="0" ixz="0" iyy="0.0036" iyz="0" izz="0.00381666666667"/>
  </inertial>
  <visual>
   <origin rpy="0 0 0.23265238929084414"xyz="155 35.73668544 116"/>
   <geometry>
    <mesh filename="Link03.stl">
   </geometry>
  </visual>
  <collision>
   <origin rpy="0 0 0.23265238929084414" xyz="180 0 -24"/>
   <geometry>
    <mesh filename="Link03_CH.stl"
   </geometry>
  </collision>
 </link>

 <joint name="joint3" type="revolute">
  <origin rpy="0 0 0.23265238929084414" xyz="0 0 0.11"/>
  <axis xyz="0 0 1"/>
  <limit effort="204" lower="-2.96705972839" upper="2.96705972839" velocity="1.91986217719"/>
  <dynamics damping="0.1"/>
  <parent link="Link03"/>
  <child link="Link04"/>
 </joint>

 <transmission name="Link3_4_trans" type="pr2_mechanism_model/SimpleTransmission">
  <actuator name="Link3_4_motor"/>
  <joint name="joint3"/>
  <mechanicalReduction>1.0</mechanicalReduction>
 </transmission>
 
 <link name="Link04">
  <inertial>
   <mass value="0">
   <origin rpy="1.5707963267948966 0 -0.23265238929084414"xyz="4.59242550e-15 -1.72919446e+01 0"/>
   <inertia ixx="0.00381666666667" ixy="0" ixz="0" iyy="0.0036" iyz="0" izz="0.00381666666667"/>
  </inertial>
  <visual>
   <origin rpy="1.5707963267948966 0 -0.23265238929084414"xyz="4.59242550e-15 -1.72919446e+01 0"/>
   <geometry>
    <mesh filename="Link04.stl">
   </geometry>
  </visual>
  <collision>
   <origin rpy="1.5707963267948966 0 -0.23265238929084414" xyz="180 0 -24"/>
   <geometry>
    <mesh filename="Link04_CH.stl"
   </geometry>
  </collision>
 </link>

 <joint name="joint4" type="revolute">
  <origin rpy="1.5707963267948966 0 -0.23265238929084414" xyz="0 0 0.11"/>
  <axis xyz="0 0 1"/>
  <limit effort="204" lower="-2.96705972839" upper="2.96705972839" velocity="1.91986217719"/>
  <dynamics damping="0.1"/>
  <parent link="Link04"/>
  <child link="Link05"/>
 </joint>
 
 <transmission name="Link_4_5_trans" type="pr2_mechanism_model/SimpleTransmission">
  <actuator name="Link_4_5_motor"/>
  <joint name="joint4"/>
  <mechanicalReduction>1.0</mechanicalReduction>
 </transmission>

 <link name="Link05">
  <inertial>
   <mass value="0">
   <origin rpy="0 0 0.2617993877991494"xyz="180 46.58742812 -24"/>
   <inertia ixx="0.00381666666667" ixy="0" ixz="0" iyy="0.0036" iyz="0" izz="0.00381666666667"/>
  </inertial>
  <visual>
   <origin rpy="0 0 0.2617993877991494"xyz="180 46.58742812 -24"/>
   <geometry>
    <mesh filename="Link05.stl">
   </geometry>
  </visual>
  <collision>
   <origin rpy="0 0 0.2617993877991494" xyz="180 0 -24"/>
   <geometry>
    <mesh filename="Link05_CH.stl"
   </geometry>
  </collision>
 </link>

 <joint name="joint5" type="revolute">
  <origin rpy="0 0 0.2617993877991494" xyz="0 0 0.11"/>
  <axis xyz="0 0 1"/>
  <limit effort="204" lower="-2.96705972839" upper="2.96705972839" velocity="1.91986217719"/>
  <dynamics damping="0.1"/>
  <parent link="Link05"/>
  <child link="Link06"/>
 </joint>

 <transmission name="Link_5_6_trans" type="pr2_mechanism_model/SimpleTransmission">
  <actuator name="Link_5_6_motor"/>
  <joint name="joint5"/>
  <mechanicalReduction>1.0</mechanicalReduction>
 </transmission>

 <link name="Link06">
  <inertial>
   <mass value="0">
   <origin rpy="0 0 -1.1344640137963142"xyz="100 -90.6307787 24"/>
   <inertia ixx="0.00381666666667" ixy="0" ixz="0" iyy="0.0036" iyz="0" izz="0.00381666666667"/>
  </inertial>
  <visual>
   <origin rpy="0 0 -1.1344640137963142"xyz="100 -90.6307787 24"/>
   <geometry>
    <mesh filename="Link06.stl">
   </geometry>
  </visual>
  <collision>
   <origin rpy="0 0 -1.1344640137963142" xyz="180 0 -24"/>
   <geometry>
    <mesh filename="Link06_CH.stl"
   </geometry>
  </collision>
 </link>

 <joint name="joint6" type="revolute">
  <origin rpy="0 0 -1.1344640137963142" xyz="0 0 0.11"/>
  <axis xyz="0 0 1"/>
  <limit effort="204" lower="-2.96705972839" upper="2.96705972839" velocity="1.91986217719"/>
  <dynamics damping="0.1"/>
  <parent link="Link06"/>
  <child link="Link07"/>
 </joint> 

 <transmission name="Link_6_7_trans" type="pr2_mechanism_model/SimpleTransmission">
  <actuator name="Link6_7_motor"/>
  <joint name="joint6"/>
  <mechanicalReduction>1.0</mechanicalReduction>
 </transmission>

 <link name="Link07">
  <inertial>
   <mass value="0">
   <origin rpy="1.5707963267948966 0 -0.4886921905584123"xyz="0 0 86"/>
   <inertia ixx="0.00381666666667" ixy="0" ixz="0" iyy="0.0036" iyz="0" izz="0.00381666666667"/>
  </inertial>
  <visual>
   <origin rpy="1.5707963267948966 0 -0.4886921905584123"xyz="0 0 86"/>
   <geometry>
    <mesh filename="Link07.stl">
   </geometry>
  </visual>
  <collision>
   <origin rpy="1.5707963267948966 0 -0.4886921905584123" xyz="180 0 -24"/>
   <geometry>
    <mesh filename="Link07_CH.stl"
   </geometry>
  </collision>
 </link>

 <joint name="joint7" type="revolute">
  <origin rpy="1.5707963267948966 0 -0.4886921905584123" xyz="0 0 0.11"/>
  <axis xyz="0 0 1"/>
  <limit effort="204" lower="-2.96705972839" upper="2.96705972839" velocity="1.91986217719"/>
  <dynamics damping="0.1"/>
  <parent link="Link07"/>
  <child link="Link08"/>
 </joint> 

 <transmission name="Link_7_8_trans" type="pr2_mechanism_model/SimpleTransmission">
  <actuator name="Link_7_8_motor"/>
  <joint name="joint7"/>
  <mechanicalReduction>1.0</mechanicalReduction>
 </transmission>

 <link name="Link08">
  <inertial>
   <mass value="0">
   <origin rpy="1.5707963267948966 0 1.5707963267948966"xyz="0 0 0"/>
   <inertia ixx="0.00381666666667" ixy="0" ixz="0" iyy="0.0036" iyz="0" izz="0.00381666666667"/>
  </inertial>
  <visual>
   <origin rpy="1.5707963267948966 0 1.5707963267948966"xyz="0 0 0"/>
   <geometry>
    <mesh filename="Link08.stl">
   </geometry>
  </visual>
  <collision>
   <origin rpy="1.5707963267948966 0 1.5707963267948966" xyz="180 0 -24"/>
   <geometry>
    <mesh filename="Link08_CH.stl"
   </geometry>
  </collision>
 </link>

 <joint name="joint8" type="revolute">
  <origin rpy="1.5707963267948966 0 1.5707963267948966" xyz="0 0 0.11"/>
  <axis xyz="0 0 1"/>
  <limit effort="204" lower="-2.96705972839" upper="2.96705972839" velocity="1.91986217719"/>
  <dynamics damping="0.1"/>
  <parent link="Link08"/>
  <child link="Link09"/>
 </joint> 

 <transmission name="Link_8_9_trans" type="pr2_mechanism_model/SimpleTransmission">
  <actuator name="Link_8_9_motor"/>
  <joint name="joint8"/>
  <mechanicalReduction>1.0</mechanicalReduction>
 </transmission>

 <link name="Link09">
  <inertial>
   <mass value="0">
   <origin rpy="-1.5707963267948966 0 0"xyz="2.14313190e-15 -1.02330097e+01  1.50500000e+02"/>
   <inertia ixx="0.00381666666667" ixy="0" ixz="0" iyy="0.0036" iyz="0" izz="0.00381666666667"/>
  </inertial>
  <visual>
   <origin rpy="-1.5707963267948966 0 -0.2967059728390361"xyz="2.14313190e-15 -1.02330097e+01  1.50500000e+02"/>
   <geometry>
    <mesh filename="Link09.stl">
   </geometry>
  </visual>
  <collision>
   <origin rpy="-1.5707963267948966 0 -0.2967059728390361" xyz="180 0 -24"/>
   <geometry>
    <mesh filename="Link09_CH.stl"
   </geometry>
  </collision>
 </link>

 <joint name="joint9" type="revolute">
  <origin rpy="-1.5707963267948966 0 -0.2967059728390361" xyz="0 0 0.11"/>
  <axis xyz="0 0 1"/>
  <limit effort="204" lower="-2.96705972839" upper="2.96705972839" velocity="1.91986217719"/>
  <dynamics damping="0.1"/>
  <parent link="Link09"/>
  <child link="Link10"/>
 </joint> 

 <transmission name="Link_9_10_trans" type="pr2_mechanism_model/SimpleTransmission">
  <actuator name="Link_9_10_motor"/>
  <joint name="joint9"/>
  <mechanicalReduction>1.0</mechanicalReduction>
 </transmission>

 <link name="Link10">
  <inertial>
   <mass value="0">
   <origin rpy="-1.5707963267948966 0 0"xyz="3.37390193e-15 0 0"/>
   <inertia ixx="0.00381666666667" ixy="0" ixz="0" iyy="0.0036" iyz="0" izz="0.00381666666667"/>
  </inertial>
  <visual>
   <origin rpy="-1.5707963267948966 0 0"xyz="3.37390193e-15 0 0"/>
   <geometry>
    <mesh filename="Link10.stl">
   </geometry>
  </visual>
  <collision>
   <origin rpy="-1.5707963267948966 0 0" xyz="180 0 -24"/>
   <geometry>
    <mesh filename="Link10_CH.stl"
   </geometry>
  </collision>
 </link>

 <joint name="joint10" type="revolute">
  <origin rpy="-1.5707963267948966 0 0" xyz="0 0 0.11"/>
  <axis xyz="0 0 1"/>
  <limit effort="204" lower="-2.96705972839" upper="2.96705972839" velocity="1.91986217719"/>
  <dynamics damping="0.1"/>
  <parent link="Link10"/>
  <child link="Link11"/>
 </joint>

 <transmission name="Link10_11_trans" type="pr2_mechanism_model/SimpleTransmission">
  <actuator name="Link10_11_motor"/>
  <joint name="joint10"/>
  <mechanicalReduction>1.0</mechanicalReduction>
 </transmission>

 <link name="Link11">
  <inertial>
   <mass value="0">
   <origin rpy="1.5707963267948966 0 0"xyz="0 0 58.65"/>
   <inertia ixx="0.00381666666667" ixy="0" ixz="0" iyy="0.0036" iyz="0" izz="0.00381666666667"/>
  </inertial>
  <visual>
   <origin rpy="1.5707963267948966 0 0"xyz="0 0 58.65"/>
   <geometry>
    <mesh filename="Link11.stl">
   </geometry>
  </visual>
  <collision>
   <origin rpy="1.5707963267948966 0 0" xyz="180 0 -24"/>
   <geometry>
    <mesh filename="Link11_CH.stl"
   </geometry>
  </collision>
 </link>
 
</robot>


  


 


 


  

