<?xml version="1.0" ?>
<!-- =================================================================================== -->
<!-- |    This document was autogenerated by xacro from kuka_lwr_arm.urdf.xacro        | -->
<!-- |    EDITING THIS FILE BY HAND IS NOT RECOMMENDED                                 | -->
<!-- =================================================================================== -->

<robot name="Right_Arm_Robot">

 <link name="Link00">
  <inertial>
   <mass value="0">
   <origin rpy="0 0 0"xyz="0 0 0"/>
   <inertia ixx="0.00381666666667" ixy="0" ixz="0" iyy="0.0036" iyz="0" izz="0.00381666666667"/>
  </inertial>
  <visual>
   <origin rpy="0 0 0"xyz="0 0 0"/>
   <geometry>
    <mesh filename="Link00.stl">
   </geometry>
  </visual>
  <collision>
   <origin rpy="0 0 0" xyz="0 0 0"/>
   <geometry>
    <mesh filename="Link00.stl"
   </geometry>
  </collision>
 </link>

 <joint name="joint0" type="revolute">
  <origin rpy="0 0 0" xyz="0 0 0.11"/>
  <axis xyz="0 0 1"/>
  <limit effort="204" lower="-2.96705972839" upper="2.96705972839" velocity="1.91986217719"/>
  <dynamics damping="0.1"/>
  <parent link="Link00"/>
  <child link="Link12"/>
 </joint> 

 <link name="Link12">
  <inertial>
   <mass value="0">
   <origin rpy="1.5707963267948966 0 0"xyz="0 0 0"/>
   <inertia ixx="0.00381666666667" ixy="0" ixz="0" iyy="0.0036" iyz="0" izz="0.00381666666667"/>
  </inertial>
  <visual>
   <origin rpy="1.5707963267948966 0 0"xyz="0 0 0"/>
   <geometry>
    <mesh filename="Link12.stl">
   </geometry>
  </visual>
  <collision>
   <origin rpy="1.5707963267948966 0 0" xyz="180 0 -24"/>
   <geometry>
    <mesh filename="Link12_CH.stl"
   </geometry>
  </collision>
 </link>
 
 <joint name="joint12" type="revolute">
  <origin rpy="1.5707963267948966 0 0" xyz="0 0 0.11"/>
  <axis xyz="0 0 1"/>
  <limit effort="204" lower="-2.96705972839" upper="2.96705972839" velocity="1.91986217719"/>
  <dynamics damping="0.1"/>
  <parent link="Link12"/>
  <child link="Link13"/>
 </joint>

 <link name="Link13">
  <inertial>
   <mass value="0">
   <origin rpy="1.5707963267948966 0 1.5707963267948966"xyz="0 0 400"/>
   <inertia ixx="0.00381666666667" ixy="0" ixz="0" iyy="0.0036" iyz="0" izz="0.00381666666667"/>
  </inertial>
  <visual>
   <origin rpy="1.5707963267948966 0 1.5707963267948966"xyz="0 0 400"/>
   <geometry>
    <mesh filename="Link13.stl">
   </geometry>
  </visual>
  <collision>
   <origin rpy="1.5707963267948966 0 1.5707963267948966" xyz="180 0 -24"/>
   <geometry>
    <mesh filename="Link13_CH.stl"
   </geometry>
  </collision>
 </link>
   
 <joint name="joint13" type="revolute">
  <origin rpy="1.5707963267948966 0 1.5707963267948966" xyz="0 0 0.11"/>
  <axis xyz="0 0 1"/>
  <limit effort="204" lower="-2.96705972839" upper="2.96705972839" velocity="1.91986217719"/>
  <dynamics damping="0.1"/>
  <parent link="Link12"/>
  <child link="Link14"/>
 </joint>

 <transmission name="kuka_arm_0_trans" type="pr2_mechanism_model/SimpleTransmission">
  <actuator name="kuka_arm_0_motor"/>
  <joint name="kuka_arm_0_joint"/>
  <mechanicalReduction>1.0</mechanicalReduction>
 </transmission>

 <link name="Link14">
  <inertial>
   <mass value="0">
   <origin rpy="0 0 0.23265238929084414"xyz="155 35.73668544 -166"/>
   <inertia ixx="0.00381666666667" ixy="0" ixz="0" iyy="0.0036" iyz="0" izz="0.00381666666667"/>
  </inertial>
  <visual>
   <origin rpy="0 0 0.23265238929084414"xyz="155 35.73668544 -166"/>
   <geometry>
    <mesh filename="Link14.stl">
   </geometry>
  </visual>
  <collision>
   <origin rpy="0 0 0.23265238929084414" xyz="180 0 -24"/>
   <geometry>
    <mesh filename="Link14_CH.stl"
   </geometry>
  </collision>
 </link>

 <joint name="joint14" type="revolute">
  <origin rpy="0 0 0.23265238929084414" xyz="0 0 0.11"/>
  <axis xyz="0 0 1"/>
  <limit effort="204" lower="-2.96705972839" upper="2.96705972839" velocity="1.91986217719"/>
  <dynamics damping="0.1"/>
  <parent link="Link14"/>
  <child link="Link15"/>
 </joint>

 <transmission name="kuka_arm_0_trans" type="pr2_mechanism_model/SimpleTransmission">
  <actuator name="kuka_arm_0_motor"/>
  <joint name="kuka_arm_0_joint"/>
  <mechanicalReduction>1.0</mechanicalReduction>
 </transmission>
 
 <link name="Link15">
  <inertial>
   <mass value="0">
   <origin rpy="1.5707963267948966 0 -0.23265238929084414"xyz=" 4.59242550e-15 -1.72919446e+01 0"/>
   <inertia ixx="0.00381666666667" ixy="0" ixz="0" iyy="0.0036" iyz="0" izz="0.00381666666667"/>
  </inertial>
  <visual>
   <origin rpy="1.5707963267948966 0 -0.23265238929084414"xyz=" 4.59242550e-15 -1.72919446e+01 0"/>
   <geometry>
    <mesh filename="Link15.stl">
   </geometry>
  </visual>
  <collision>
   <origin rpy="1.5707963267948966 0 -0.23265238929084414" xyz="180 0 -24"/>
   <geometry>
    <mesh filename="Link15_CH.stl"
   </geometry>
  </collision>
 </link>

 <joint name="joint15" type="revolute">
  <origin rpy="1.5707963267948966 0 -0.23265238929084414" xyz="0 0 0.11"/>
  <axis xyz="0 0 1"/>
  <limit effort="204" lower="-2.96705972839" upper="2.96705972839" velocity="1.91986217719"/>
  <dynamics damping="0.1"/>
  <parent link="Link15"/>
  <child link="Link16"/>
 </joint>

 <transmission name="kuka_arm_0_trans" type="pr2_mechanism_model/SimpleTransmission">
  <actuator name="kuka_arm_0_motor"/>
  <joint name="kuka_arm_0_joint"/>
  <mechanicalReduction>1.0</mechanicalReduction>
 </transmission>
 
 <link name="Link16">
  <inertial>
   <mass value="0">
   <origin rpy="0 0 -0.2617993877991494"xyz="180 -46.58742812 -24"/>
   <inertia ixx="0.00381666666667" ixy="0" ixz="0" iyy="0.0036" iyz="0" izz="0.00381666666667"/>
  </inertial>
  <visual>
   <origin rpy="0 0 -0.2617993877991494"xyz="180 -46.58742812 -24"/>
   <geometry>
    <mesh filename="Link16.stl">
   </geometry>
  </visual>
  <collision>
   <origin rpy="0 0 -0.2617993877991494" xyz="180 0 -24"/>
   <geometry>
    <mesh filename="Link16_CH.stl"
   </geometry>
  </collision>
 </link>

 <joint name="joint16" type="revolute">
  <origin rpy="0 0 -0.2617993877991494" xyz="0 0 0.11"/>
  <axis xyz="0 0 1"/>
  <limit effort="204" lower="-2.96705972839" upper="2.96705972839" velocity="1.91986217719"/>
  <dynamics damping="0.1"/>
  <parent link="Link16"/>
  <child link="Link17"/>
 </joint>

 <transmission name="kuka_arm_0_trans" type="pr2_mechanism_model/SimpleTransmission">
  <actuator name="kuka_arm_0_motor"/>
  <joint name="kuka_arm_0_joint"/>
  <mechanicalReduction>1.0</mechanicalReduction>
 </transmission>

 <link name="Link17">
  <inertial>
   <mass value="0">
   <origin rpy="0 0 1.1344640137963142"xyz="100 90.6307787  24"/>
   <inertia ixx="0.00381666666667" ixy="0" ixz="0" iyy="0.0036" iyz="0" izz="0.00381666666667"/>
  </inertial>
  <visual>
   <origin rpy="0 0 1.1344640137963142"xyz="100 90.6307787  24"/>
   <geometry>
    <mesh filename="Link17.stl">
   </geometry>
  </visual>
  <collision>
   <origin rpy="0 0 1.1344640137963142" xyz="180 0 -24"/>
   <geometry>
    <mesh filename="Link17_CH.stl"
   </geometry>
  </collision>
 </link>

 <joint name="joint17" type="revolute">
  <origin rpy="0 0 1.1344640137963142" xyz="0 0 0.11"/>
  <axis xyz="0 0 1"/>
  <limit effort="204" lower="-2.96705972839" upper="2.96705972839" velocity="1.91986217719"/>
  <dynamics damping="0.1"/>
  <parent link="Link17"/>
  <child link="Link18"/>
 </joint> 

 <transmission name="kuka_arm_0_trans" type="pr2_mechanism_model/SimpleTransmission">
  <actuator name="kuka_arm_0_motor"/>
  <joint name="kuka_arm_0_joint"/>
  <mechanicalReduction>1.0</mechanicalReduction>
 </transmission>

 <link name="Link18">
  <inertial>
   <mass value="0">
   <origin rpy="1.5707963267948966 0 0.4886921905584123"xyz="0 0 86"/>
   <inertia ixx="0.00381666666667" ixy="0" ixz="0" iyy="0.0036" iyz="0" izz="0.00381666666667"/>
  </inertial>
  <visual>
   <origin rpy="1.5707963267948966 0 0.4886921905584123"xyz="0 0 86"/>
   <geometry>
    <mesh filename="Link18.stl">
   </geometry>
  </visual>
  <collision>
   <origin rpy="1.5707963267948966 0 0.4886921905584123" xyz="180 0 -24"/>
   <geometry>
    <mesh filename="Link18_CH.stl"
   </geometry>
  </collision>
 </link>

 <joint name="joint18" type="revolute">
  <origin rpy="1.5707963267948966 0 0.4886921905584123" xyz="0 0 0.11"/>
  <axis xyz="0 0 1"/>
  <limit effort="204" lower="-2.96705972839" upper="2.96705972839" velocity="1.91986217719"/>
  <dynamics damping="0.1"/>
  <parent link="Link18"/>
  <child link="Link19"/>
 </joint> 

 <transmission name="kuka_arm_0_trans" type="pr2_mechanism_model/SimpleTransmission">
  <actuator name="kuka_arm_0_motor"/>
  <joint name="kuka_arm_0_joint"/>
  <mechanicalReduction>1.0</mechanicalReduction>
 </transmission>

 <link name="Link19">
  <inertial>
   <mass value="0">
   <origin rpy="1.5707963267948966 0 1.5707963267948966"xyz="0 0 0"/>
   <inertia ixx="0.00381666666667" ixy="0" ixz="0" iyy="0.0036" iyz="0" izz="0.00381666666667"/>
  </inertial>
  <visual>
   <origin rpy="0 0 0"xyz="0 0 0"/>
   <geometry>
    <mesh filename="Link19.stl">
   </geometry>
  </visual>
  <collision>
   <origin rpy="1.5707963267948966 0 1.5707963267948966" xyz="180 0 -24"/>
   <geometry>
    <mesh filename="Link19_CH.stl"
   </geometry>
  </collision>
 </link>

 <joint name="joint19" type="revolute">
  <origin rpy="1.5707963267948966 0 1.5707963267948966" xyz="0 0 0.11"/>
  <axis xyz="0 0 1"/>
  <limit effort="204" lower="-2.96705972839" upper="2.96705972839" velocity="1.91986217719"/>
  <dynamics damping="0.1"/>
  <parent link="Link19"/>
  <child link="Link20"/>
 </joint> 

 <transmission name="kuka_arm_0_trans" type="pr2_mechanism_model/SimpleTransmission">
  <actuator name="kuka_arm_0_motor"/>
  <joint name="kuka_arm_0_joint"/>
  <mechanicalReduction>1.0</mechanicalReduction>
 </transmission>

 <link name="Link20">
  <inertial>
   <mass value="0">
   <origin rpy="-1.5707963267948966 0 0.2967059728390361"xyz="2.14313190e-15 1.02330097e+01 1.50500000e+02"/>
   <inertia ixx="0.00381666666667" ixy="0" ixz="0" iyy="0.0036" iyz="0" izz="0.00381666666667"/>
  </inertial>
  <visual>
   <origin rpy="-1.5707963267948966 0 0.2967059728390361"xyz="2.14313190e-15 1.02330097e+01 1.50500000e+02"/>
   <geometry>
    <mesh filename="Link20.stl">
   </geometry>
  </visual>
  <collision>
   <origin rpy="-1.5707963267948966 0 0.2967059728390361" xyz="180 0 -24"/>
   <geometry>
    <mesh filename="Link20_CH.stl"
   </geometry>
  </collision>
 </link>

 <joint name="joint20" type="revolute">
  <origin rpy="-1.5707963267948966 0 0.2967059728390361" xyz="0 0 0"/>
  <axis xyz="0 0 1"/>
  <limit effort="204" lower="-2.96705972839" upper="2.96705972839" velocity="1.91986217719"/>
  <dynamics damping="0.1"/>
  <parent link="Link20"/>
  <child link="Link21"/>
 </joint> 

 <transmission name="kuka_arm_0_trans" type="pr2_mechanism_model/SimpleTransmission">
  <actuator name="kuka_arm_0_motor"/>
  <joint name="kuka_arm_0_joint"/>
  <mechanicalReduction>1.0</mechanicalReduction>
 </transmission>

 <link name="Link21">
  <inertial>
   <mass value="0">
   <origin rpy="-1.5707963267948966 0 0"xyz="3.37390193e-15 0 0"/>
   <inertia ixx="0.00381666666667" ixy="0" ixz="0" iyy="0.0036" iyz="0" izz="0.00381666666667"/>
  </inertial>
  <visual>
   <origin rpy="-1.5707963267948966 0 0"xyz="3.37390193e-15 0 0"/>
   <geometry>
    <mesh filename="Link21.stl">
   </geometry>
  </visual>
  <collision>
   <origin rpy="-1.5707963267948966 0 0" xyz="180 0 -24"/>
   <geometry>
    <mesh filename="Link21_CH.stl"
   </geometry>
  </collision>
 </link>

 <joint name="joint21" type="revolute">
  <origin rpy="-1.5707963267948966 0 0" xyz="0 0 0.11"/>
  <axis xyz="0 0 1"/>
  <limit effort="204" lower="-2.96705972839" upper="2.96705972839" velocity="1.91986217719"/>
  <dynamics damping="0.1"/>
  <parent link="Link21"/>
  <child link="Link22"/>
 </joint>

 <transmission name="kuka_arm_0_trans" type="pr2_mechanism_model/SimpleTransmission">
  <actuator name="kuka_arm_0_motor"/>
  <joint name="kuka_arm_0_joint"/>
  <mechanicalReduction>1.0</mechanicalReduction>
 </transmission>

 <link name="Link11">
  <inertial>
   <mass value="0">
   <origin rpy="1.5707963267948966 0 0"xyz="0 0 58.65"/>
   <inertia ixx="0.00381666666667" ixy="0" ixz="0" iyy="0.0036" iyz="0" izz="0.00381666666667"/>
  </inertial>
  <visual>
   <origin rpy="1.5707963267948966 0 0"xyz="0 0 58.65"/>
   <geometry>
    <mesh filename="Link11.stl">
   </geometry>
  </visual>
  <collision>
   <origin rpy="1.5707963267948966 0 0" xyz="180 0 -24"/>
   <geometry>
    <mesh filename="Link11_CH.stl"
   </geometry>
  </collision>
 </link>
 
</robot>