<?xml version="1.0" ?>
<!-- =================================================================================== -->
<!-- |    This document was autogenerated by xacro from kuka_lwr_arm.urdf.xacro        | -->
<!-- |    EDITING THIS FILE BY HAND IS NOT RECOMMENDED                                 | -->
<!-- =================================================================================== -->

<robot name="Housden_Robot">
 <link name="Link01">
  <inetial>
   <mass value="0">
   <origin rpy="0 0 0"xyz="0 0 0"/>
   <inertia ixx="0.00381666666667" ixy="0" ixz="0" iyy="0.0036" iyz="0" izz="0.00381666666667"/>
  </inertial>
  <visual>
   <origin rpy="0 0 0"xyz="0 0 0"/>
   <geometry>
    <mesh filename="Link01.stl">
   </geometry>
  </visual>
  <collision>
   <origin rpy="0 0 0" xyz="180 0 -24"/>
   <geometry>
    <mesh filename="Link01.stl"
   </geometry>
  </collision>
 </link>
  
  <joint name="joint1" type="revolute">
   <origin rpy="0 0 0" xyz="0 0 0.11"/>
   <axis xyz="0 0 1"/>
   <limit effort="204" lower="-2.96705972839" upper="2.96705972839" velocity="1.91986217719"/>
   <dynamics damping="0.1"/>
   <parent link="Link01"/>
   <child link="Link02"/>
  </joint>

 <link name="Link02">
  <inetial>
   <mass value="0">
   <origin rpy="0 0 0"xyz="0 0 0"/>
   <inertia ixx="0.00381666666667" ixy="0" ixz="0" iyy="0.0036" iyz="0" izz="0.00381666666667"/>
  </inertial>
  <visual>
   <origin rpy="0 0 0"xyz="0 0 0"/>
   <geometry>
    <mesh filename="Link02.stl">
   </geometry>
  </visual>
  <collision>
   <origin rpy="0 0 0" xyz="180 0 -24"/>
   <geometry>
    <mesh filename="Link02_CH.stl"
   </geometry>
  </collision>
 </link>
  
 <joint name="joint2" type="revolute">
  <origin rpy="0 0 0" xyz="0 0 0.11"/>
  <axis xyz="0 0 1"/>
  <limit effort="204" lower="-2.96705972839" upper="2.96705972839" velocity="1.91986217719"/>
  <dynamics damping="0.1"/>
  <parent link="Link02"/>
  <child link="Link03"/>
 </joint>

 <link name="Link01">
  <inetial>
   <mass value="0">
   <origin rpy="0 0 0"xyz="0 0 0"/>
   <inertia ixx="0.00381666666667" ixy="0" ixz="0" iyy="0.0036" iyz="0" izz="0.00381666666667"/>
  </inertial>
  <visual>
   <origin rpy="0 0 0"xyz="0 0 0"/>
   <geometry>
    <mesh filename="Link01.stl">
   </geometry>
  </visual>
  <collision>
   <origin rpy="0 0 0" xyz="180 0 -24"/>
   <geometry>
    <mesh filename="Link01.stl"
   </geometry>
  </collision>
 </link>

 <transmission name="Link0102transmission" type="pr2_mechanism_model/SimpleTransmission">
    <actuator name="Link0102motor"/>
    <joint name="joint1"/>
    <mechanicalReduction>1.0</mechanicalReduction>
 </transmission>
 
 


 


  

