<?xml version="1.0" ?>
<!-- =================================================================================== -->
<!-- |    This document was autogenerated by xacro from kuka_lwr_arm.urdf.xacro        | -->
<!-- |    EDITING THIS FILE BY HAND IS NOT RECOMMENDED                                 | -->
<!-- =================================================================================== -->

<robot name="Left_Arm_Robot">

 <link name="Link00">
  <inetial>
   <mass value="0">
   <origin rpy="0 0 0"xyz="0 0 0"/>
   <inertia ixx="0.00381666666667" ixy="0" ixz="0" iyy="0.0036" iyz="0" izz="0.00381666666667"/>
  </inertial>
  <visual>
   <origin rpy="0 0 0"xyz="0 0 0"/>
   <geometry>
    <mesh filename="Link00.stl">
   </geometry>
  </visual>
  <collision>
   <origin rpy="0 0 0" xyz="180 0 -24"/>
   <geometry>
    <mesh filename="Link00.stl"
   </geometry>
  </collision>
 </link>

 <joint name="joint0" type="revolute">
  <origin rpy="0 0 0" xyz="0 0 0.11"/>
  <axis xyz="0 0 1"/>
  <limit effort="204" lower="-2.96705972839" upper="2.96705972839" velocity="1.91986217719"/>
  <dynamics damping="0.1"/>
  <parent link="Link00"/>
  <child link="Link01"/>
 </joint> 

 <link name="Link01">
  <inetial>
   <mass value="0">
   <origin rpy="0 0 0"xyz="0 0 0"/>
   <inertia ixx="0.00381666666667" ixy="0" ixz="0" iyy="0.0036" iyz="0" izz="0.00381666666667"/>
  </inertial>
  <visual>
   <origin rpy="0 0 0"xyz="0 0 0"/>
   <geometry>
    <mesh filename="Link01.stl">
   </geometry>
  </visual>
  <collision>
   <origin rpy="0 0 0" xyz="180 0 -24"/>
   <geometry>
    <mesh filename="Link01.stl"
   </geometry>
  </collision>
 </link>
 
 <joint name="joint1" type="revolute">
  <origin rpy="0 0 0" xyz="0 0 0.11"/>
  <axis xyz="0 0 1"/>
  <limit effort="204" lower="-2.96705972839" upper="2.96705972839" velocity="1.91986217719"/>
  <dynamics damping="0.1"/>
  <parent link="Link01"/>
  <child link="Link02"/>
 </joint>

 <link name="Link02">
  <inetial>
   <mass value="0">
   <origin rpy="0 0 0"xyz="0 0 0"/>
   <inertia ixx="0.00381666666667" ixy="0" ixz="0" iyy="0.0036" iyz="0" izz="0.00381666666667"/>
  </inertial>
  <visual>
   <origin rpy="0 0 0"xyz="0 0 0"/>
   <geometry>
    <mesh filename="Link02.stl">
   </geometry>
  </visual>
  <collision>
   <origin rpy="0 0 0" xyz="180 0 -24"/>
   <geometry>
    <mesh filename="Link02_CH.stl"
   </geometry>
  </collision>
 </link>
   
 <joint name="joint2" type="revolute">
  <origin rpy="0 0 0" xyz="0 0 0.11"/>
  <axis xyz="0 0 1"/>
  <limit effort="204" lower="-2.96705972839" upper="2.96705972839" velocity="1.91986217719"/>
  <dynamics damping="0.1"/>
  <parent link="Link02"/>
  <child link="Link03"/>
 </joint>

 <link name="Link03">
  <inetial>
   <mass value="0">
   <origin rpy="0 0 0"xyz="0 0 0"/>
   <inertia ixx="0.00381666666667" ixy="0" ixz="0" iyy="0.0036" iyz="0" izz="0.00381666666667"/>
  </inertial>
  <visual>
   <origin rpy="0 0 0"xyz="0 0 0"/>
   <geometry>
    <mesh filename="Link03.stl">
   </geometry>
  </visual>
  <collision>
   <origin rpy="0 0 0" xyz="180 0 -24"/>
   <geometry>
    <mesh filename="Link03_CH.stl"
   </geometry>
  </collision>
 </link>

 <joint name="joint3" type="">
  <origin rpy="0 0 0" xyz="0 0 0.11"/>
  <axis xyz="0 0 1"/>
  <limit effort="204" lower="-2.96705972839" upper="2.96705972839" velocity="1.91986217719"/>
  <dynamics damping="0.1"/>
  <parent link="Link03"/>
  <child link="Link04"/>
 </joint>
 
 <link name="Link04">
  <inertial>
   <mass value="0">
   <origin rpy="0 0 0"xyz="0 0 0"/>
   <inertia ixx="0.00381666666667" ixy="0" ixz="0" iyy="0.0036" iyz="0" izz="0.00381666666667"/>
  </inertial>
  <visual>
   <origin rpy="0 0 0"xyz="0 0 0"/>
   <geometry>
    <mesh filename="Link04.stl">
   </geometry>
  </visual>
  <collision>
   <origin rpy="0 0 0" xyz="180 0 -24"/>
   <geometry>
    <mesh filename="Link04_CH.stl"
   </geometry>
  </collision>
 </link>

 <joint name="joint4" type="revolute">
  <origin rpy="0 0 0" xyz="0 0 0.11"/>
  <axis xyz="0 0 1"/>
  <limit effort="204" lower="-2.96705972839" upper="2.96705972839" velocity="1.91986217719"/>
  <dynamics damping="0.1"/>
  <parent link="Link04"/>
  <child link="Link05"/>
 </joint>
 
 <link name="Link05">
  <inertial>
   <mass value="0">
   <origin rpy="0 0 0"xyz="0 0 0"/>
   <inertia ixx="0.00381666666667" ixy="0" ixz="0" iyy="0.0036" iyz="0" izz="0.00381666666667"/>
  </inertial>
  <visual>
   <origin rpy="0 0 0"xyz="0 0 0"/>
   <geometry>
    <mesh filename="Link05.stl">
   </geometry>
  </visual>
  <collision>
   <origin rpy="0 0 0" xyz="180 0 -24"/>
   <geometry>
    <mesh filename="Link05_CH.stl"
   </geometry>
  </collision>
 </link>

 <joint name="joint5" type="revolute">
  <origin rpy="0 0 0" xyz="0 0 0.11"/>
  <axis xyz="0 0 1"/>
  <limit effort="204" lower="-2.96705972839" upper="2.96705972839" velocity="1.91986217719"/>
  <dynamics damping="0.1"/>
  <parent link="Link05"/>
  <child link="Link06"/>
 </joint>

 <link name="Link06">
  <inertial>
   <mass value="0">
   <origin rpy="0 0 0"xyz="0 0 0"/>
   <inertia ixx="0.00381666666667" ixy="0" ixz="0" iyy="0.0036" iyz="0" izz="0.00381666666667"/>
  </inertial>
  <visual>
   <origin rpy="0 0 0"xyz="0 0 0"/>
   <geometry>
    <mesh filename="Link06.stl">
   </geometry>
  </visual>
  <collision>
   <origin rpy="0 0 0" xyz="180 0 -24"/>
   <geometry>
    <mesh filename="Link06_CH.stl"
   </geometry>
  </collision>
 </link>

 <joint name="joint6" type="revolute">
  <origin rpy="0 0 0" xyz="0 0 0.11"/>
  <axis xyz="0 0 1"/>
  <limit effort="204" lower="-2.96705972839" upper="2.96705972839" velocity="1.91986217719"/>
  <dynamics damping="0.1"/>
  <parent link="Link06"/>
  <child link="Link07"/>
 </joint> 

 <link name="Link07">
  <inertial>
   <mass value="0">
   <origin rpy="0 0 0"xyz="0 0 0"/>
   <inertia ixx="0.00381666666667" ixy="0" ixz="0" iyy="0.0036" iyz="0" izz="0.00381666666667"/>
  </inertial>
  <visual>
   <origin rpy="0 0 0"xyz="0 0 0"/>
   <geometry>
    <mesh filename="Link07.stl">
   </geometry>
  </visual>
  <collision>
   <origin rpy="0 0 0" xyz="180 0 -24"/>
   <geometry>
    <mesh filename="Link07_CH.stl"
   </geometry>
  </collision>
 </link>

 <joint name="joint7" type="revolute">
  <origin rpy="0 0 0" xyz="0 0 0.11"/>
  <axis xyz="0 0 1"/>
  <limit effort="204" lower="-2.96705972839" upper="2.96705972839" velocity="1.91986217719"/>
  <dynamics damping="0.1"/>
  <parent link="Link07"/>
  <child link="Link08"/>
 </joint> 

 <link name="Link08">
  <inertial>
   <mass value="0">
   <origin rpy="0 0 0"xyz="0 0 0"/>
   <inertia ixx="0.00381666666667" ixy="0" ixz="0" iyy="0.0036" iyz="0" izz="0.00381666666667"/>
  </inertial>
  <visual>
   <origin rpy="0 0 0"xyz="0 0 0"/>
   <geometry>
    <mesh filename="Link08.stl">
   </geometry>
  </visual>
  <collision>
   <origin rpy="0 0 0" xyz="180 0 -24"/>
   <geometry>
    <mesh filename="Link08_CH.stl"
   </geometry>
  </collision>
 </link>

 <joint name="joint8" type="revolute">
  <origin rpy="0 0 0" xyz="0 0 0.11"/>
  <axis xyz="0 0 1"/>
  <limit effort="204" lower="-2.96705972839" upper="2.96705972839" velocity="1.91986217719"/>
  <dynamics damping="0.1"/>
  <parent link="Link08"/>
  <child link="Link09"/>
 </joint> 

 <link name="Link09">
  <inertial>
   <mass value="0">
   <origin rpy="0 0 0"xyz="0 0 0"/>
   <inertia ixx="0.00381666666667" ixy="0" ixz="0" iyy="0.0036" iyz="0" izz="0.00381666666667"/>
  </inertial>
  <visual>
   <origin rpy="0 0 0"xyz="0 0 0"/>
   <geometry>
    <mesh filename="Link09.stl">
   </geometry>
  </visual>
  <collision>
   <origin rpy="0 0 0" xyz="180 0 -24"/>
   <geometry>
    <mesh filename="Link09_CH.stl"
   </geometry>
  </collision>
 </link>

 <joint name="joint9" type="revolute">
  <origin rpy="0 0 0" xyz="0 0 0.11"/>
  <axis xyz="0 0 1"/>
  <limit effort="204" lower="-2.96705972839" upper="2.96705972839" velocity="1.91986217719"/>
  <dynamics damping="0.1"/>
  <parent link="Link09"/>
  <child link="Link10"/>
 </joint> 

 <link name="Link10">
  <inertial>
   <mass value="0">
   <origin rpy="0 0 0"xyz="0 0 0"/>
   <inertia ixx="0.00381666666667" ixy="0" ixz="0" iyy="0.0036" iyz="0" izz="0.00381666666667"/>
  </inertial>
  <visual>
   <origin rpy="0 0 0"xyz="0 0 0"/>
   <geometry>
    <mesh filename="Link10.stl">
   </geometry>
  </visual>
  <collision>
   <origin rpy="0 0 0" xyz="180 0 -24"/>
   <geometry>
    <mesh filename="Link10_CH.stl"
   </geometry>
  </collision>
 </link>

 <joint name="joint10" type="revolute">
  <origin rpy="0 0 0" xyz="0 0 0.11"/>
  <axis xyz="0 0 1"/>
  <limit effort="204" lower="-2.96705972839" upper="2.96705972839" velocity="1.91986217719"/>
  <dynamics damping="0.1"/>
  <parent link="Link10"/>
  <child link="Link11"/>
 </joint>

 <link name="Link11">
  <inertial>
   <mass value="0">
   <origin rpy="0 0 0"xyz="0 0 0"/>
   <inertia ixx="0.00381666666667" ixy="0" ixz="0" iyy="0.0036" iyz="0" izz="0.00381666666667"/>
  </inertial>
  <visual>
   <origin rpy="0 0 0"xyz="0 0 0"/>
   <geometry>
    <mesh filename="Link11.stl">
   </geometry>
  </visual>
  <collision>
   <origin rpy="0 0 0" xyz="180 0 -24"/>
   <geometry>
    <mesh filename="Link11_CH.stl"
   </geometry>
  </collision>
 </link>
 
</robot>


  


 


 


  

